Workbook
Name PRINT1: A!$A$1:$L$61
Name PRINT2: A!$M$64:$Y$67
Name PRINT3: A!#REF!
Name PRINT4: A!#REF!

Sheet A
A1: GWRS AWPF SAMPLE SCHEDULE
F3: Revised May 1, 2023
B4: \
E5: changes to schedule are printed in reverse text
B9: Q-1 | C9: MFF | D9: MFE | E9: MFC | F9: ROF | G9: ROP | H9: ROC | I9: UVF | J9: UVP | K9: DPW | L9: FPW
A10: EC | B10: WG/MC | C10: COL | D10: QG | F10: WG/COL | G10: WG/COL | K10: COL | L10: DG/COL
A11: TDS | B11: WC | F11: WG | G11: WG | H11: WG | L11: WG
A12: pH | B12: WG | C12: WG/COL | D12: WG | F12: WG/COL | G12: WG/COL | H12: MG | J12: WG | K12: COL | L12: WG/COL
A13: Na | B13: MC | F13: MG | G13: MG | H13: MG | L13: MG
A14: K/Mg | B14: MC | F14: MG | G14: MG | H14: MG | L14: MG
A15: Ca | B15: MC | F15: MG | G15: MG | H15: MG | L15: WG
A16: Ca Hardness | K16: WG | L16: WG
A17: Fe | B17: MC | F17: MG | G17: MG | H17: MG | L17: AG/QG
A18: Mn | B18: MC | F18: MG | G18: MG | H18: MG | L18: AG/QG
A19: Trace Elements1 | B19: MC | F19: MG | G19: MG | H19: MG | L19: QG
A20: Priority Pollutants2 | L20: QG
A21: CEC (full) | F21: QG | G21: QG | L21: QG
A22: NH3-N | B22: WG | G22: WG | L22: 2WG/MG
A23: Org-N / TKN | B23: WG | G23: WG | L23: 2WG/MG
A24: Total Alkalinity | B24: MC | F24: MG | G24: MG | L24: WG
A25: OH/CO3/HCO3 | F25: MG | G25: MG | L25: MG
A26: TH | B26: MC | F26: MG | G26: MG | H26: MG | L26: MG
A27: F | B27: MC | L27: QG
A28: Cl | B28: MC | F28: MG | G28: MG | J28: MG | L28: MG
A29: Br | L29: MG
A30: NO3-N | B30: WG | G30: WC | L30: 2WG/MG
A31: NO2-N | B31: WG | G31: WC | L31: 2WG/MG
A32: NO3+NO2-N | B32: WG | G32: HWC | L32: 2WG/MG
A33: TIN / Total Nitrogen | L33: 2WG/MG
A34: PO4-P (ortho) | B34: WC | H34: WG | L34: QG
A35: SO4 | B35: MC | F35: MG | G35: MG | H35: MG | L35: MG
A36: B | B36: MC | F36: MG | G36: MG | L36: QG
A37: SiO2 | B37: MC | F37: MG | G37: MG | H37: MG | L37: QG
A38: BOD* | B38: QC | L38: MC
A39: Inorganic DBPs | L39: QG
A40: DOC | L40: QG
A41: TOC | B41: DC/WG | C41: WG | F41: DC/COL | G41: DC/COL | L41: WG (Fri.)
A42: UV%T-254/UVAB | D42: MG | I42: DC/COL | L42: QG
A43: MBAS | B43: MC | F43: MC | G43: MC | L43: AG
A44: Suspended Solids | B44: QC | C44: WG | D44: WG | E44: MG | L44: MC/QG
...

Sheet Expanded list
B1: Q-1 | C1: MFF | D1: MFE | E1: MFC | F1: ROF | G1: ROP | H1: ROC | I1: UVF | J1: UVP | K1: DPW | L1: FPW | M1: Method
A2: EC | B2: WG/MC | C2: COL | D2: QG | F2: WG/COL | G2: WG/COL | K2: COL | L2: DG/COL | M2: =_xlfn.XLOOKUP(A2,'Method list'!$C$3:$C$132,'Method list'!$B$3:$B$132) -> 2510B
A3: TDS | B3: WC | F3: WG | G3: WG | H3: WG | L3: WG | M3: =_xlfn.XLOOKUP(A3,'Method list'!$C$3:$C$132,'Method list'!$B$3:$B$132) -> 2540C
A4: pH | B4: WG | C4: WG/COL | D4: WG | F4: WG/COL | G4: WG/COL | H4: MG | J4: WG | K4: COL | L4: WG/COL | M4: =_xlfn.XLOOKUP(A4,'Method list'!$C$3:$C$132,'Method list'!$B$3:$B$132) -> 4500H+B
A5: Na | B5: MC | F5: MG | G5: MG | H5: MG | L5: MG | M5: =_xlfn.XLOOKUP(A5,'Method list'!$C$3:$C$132,'Method list'!$B$3:$B$132) -> X200.7
A6: K/Mg | B6: MC | F6: MG | G6: MG | H6: MG | L6: MG | M6: X200.7
A7: Ca | B7: MC | F7: MG | G7: MG | H7: MG | L7: WG | M7: =_xlfn.XLOOKUP(A7,'Method list'!$C$3:$C$132,'Method list'!$B$3:$B$132) -> X200.7
A8: Ca Hardness | K8: WG | L8: WG | M8: ?
A9: Fe | B9: MC | F9: MG | G9: MG | H9: MG | L9: AG/QG | M9: =_xlfn.XLOOKUP(A9,'Method list'!$C$3:$C$132,'Method list'!$B$3:$B$132) -> X200.7
A10: Mn | B10: MC | F10: MG | G10: MG | H10: MG | L10: AG/QG | M10: =_xlfn.XLOOKUP(A10,'Method list'!$C$3:$C$132,'Method list'!$B$3:$B$132) -> X200.8
A11: Trace Elements1 | B11: MC | F11: MG | G11: MG | H11: MG | L11: QG | M11: ?
A12: Priority Pollutants2 | L12: QG | M12: ?
A13: CEC (full) | F13: QG | G13: QG | L13: QG | M13: ?
A14: NH3-N | B14: WG | G14: WG | L14: 2WG/MG | M14: =_xlfn.XLOOKUP(A14,'Method list'!$C$3:$C$132,'Method list'!$B$3:$B$132) -> 4500NH3H
A15: Org-N / TKN | B15: WG | G15: WG | L15: 2WG/MG | M15: ?
A16: Total Alkalinity | B16: MC | F16: MG | G16: MG | L16: WG | M16: 2320B
A17: OH/CO3/HCO3 | F17: MG | G17: MG | L17: MG | M17: ?
A18: TH | B18: MC | F18: MG | G18: MG | H18: MG | L18: MG | M18: ?
A19: F | B19: MC | L19: QG | M19: =_xlfn.XLOOKUP(A19,'Method list'!$C$3:$C$132,'Method list'!$B$3:$B$132) -> X1-300.0
A20: Cl | B20: MC | F20: MG | G20: MG | J20: MG | L20: MG | M20: =_xlfn.XLOOKUP(A20,'Method list'!$C$3:$C$132,'Method list'!$B$3:$B$132) -> X1-300.0
A21: Br | L21: MG | M21: =_xlfn.XLOOKUP(A21,'Method list'!$C$3:$C$132,'Method list'!$B$3:$B$132) -> 300.1B
A22: NO3-N | B22: WG | G22: WC | L22: 2WG/MG | M22: =_xlfn.XLOOKUP(A22,'Method list'!$C$3:$C$132,'Method list'!$B$3:$B$132) -> 4500NO3F
A23: NO2-N | B23: WG | G23: WC | L23: 2WG/MG | M23: =_xlfn.XLOOKUP(A23,'Method list'!$C$3:$C$132,'Method list'!$B$3:$B$132) -> 4500NO3F
A24: NO3+NO2-N | B24: WG | G24: HWC | L24: 2WG/MG | M24: =_xlfn.XLOOKUP(A24,'Method list'!$C$3:$C$132,'Method list'!$B$3:$B$132) -> #N/A
A25: TIN / Total Nitrogen | L25: 2WG/MG | M25: X1-351.2
A26: PO4-P (ortho) | B26: WC | H26: WG | L26: QG | M26: 365.1
A27: SO4 | B27: MC | F27: MG | G27: MG | H27: MG | L27: MG | M27: =_xlfn.XLOOKUP(A27,'Method list'!$C$3:$C$132,'Method list'!$B$3:$B$132) -> X1-300.0
A28: B | B28: MC | F28: MG | G28: MG | L28: QG | M28: =_xlfn.XLOOKUP(A28,'Method list'!$C$3:$C$132,'Method list'!$B$3:$B$132) -> X200.7
A29: SiO2 | B29: MC | F29: MG | G29: MG | H29: MG | L29: QG | M29: =_xlfn.XLOOKUP(A29,'Method list'!$C$3:$C$132,'Method list'!$B$3:$B$132) -> 4500SIOC
A30: BOD* | B30: QC | L30: MC | M30: =_xlfn.XLOOKUP(A30,'Method list'!$C$3:$C$132,'Method list'!$B$3:$B$132) -> #N/A
A31: Inorganic DBPs | L31: QG | M31: =_xlfn.XLOOKUP(A31,'Method list'!$C$3:$C$132,'Method list'!$B$3:$B$132) -> #N/A
A32: DOC | L32: QG | M32: =_xlfn.XLOOKUP(A32,'Method list'!$C$3:$C$132,'Method list'!$B$3:$B$132) -> 5310C
A33: TOC | B33: DC/WG | C33: WG | F33: DC/COL | G33: DC/COL | L33: WG (Fri.) | M33: =_xlfn.XLOOKUP(A33,'Method list'!$C$3:$C$132,'Method list'!$B$3:$B$132) -> 5310C
A34: UV%T-254/UVAB | D34: MG | I34: DC/COL | L34: QG | M34: =_xlfn.XLOOKUP(A34,'Method list'!$C$3:$C$132,'Method list'!$B$3:$B$132) -> #N/A
A35: MBAS | B35: MC | F35: MC | G35: MC | L35: AG | M35: =_xlfn.XLOOKUP(A35,'Method list'!$C$3:$C$132,'Method list'!$B$3:$B$132) -> 5540C
A36: Suspended Solids | B36: QC | C36: WG | D36: WG | E36: MG | L36: MC/QG | M36: =_xlfn.XLOOKUP(A36,'Method list'!$C$3:$C$132,'Method list'!$B$3:$B$132) -> #N/A
A37: Color | B37: MC | F37: MC | G37: MC | L37: AG | M37: =_xlfn.XLOOKUP(A37,'Method list'!$C$3:$C$132,'Method list'!$B$3:$B$132) -> #N/A
A38: CN | B38: MG | F38: MG | G38: MG | L38: QG | M38: =_xlfn.XLOOKUP(A38,'Method list'!$C$3:$C$132,'Method list'!$B$3:$B$132) -> X1-335.4
A39: Residual Cl2 | C39: WG/COL | D39: WG/COL | F39: WG/COL | G39: WG/COL | I39: COL | L39: QG
A40: Total Coliforms | B40: WG | C40: WG | D40: WG | G40: WG | L40: DG
...

Sheet Method list
A1: COMMON INORGANIC TEST-SERIES
A2: Parameter Name | B2: Method | C2: Parameter Abbrev. | D2: GENLVLII | E2: RO-COMM | F2: METALS
A3: Adjusted Sodium Adsorption Ratio | B3: X200.7 | C3: SARADJ
A4: Aggressive Index | B4: AI | C4: AI
A5: Alkalinity-Phenolphthalein | B5: 2320B | C5: ALKPHE | D5: ALKPHE | E5: ALKPHE
A6: Aluminum | B6: X200.8 | C6: Al | D6: Al | E6: Al | F6: Al
A7: Aluminum (dissolved) | B7: X200.8D | C7: Al-DIS
A8: Ammonia Nitrogen | B8: 4500NH3H | C8: NH3-N | E8: NH3-N
A9: Antimony | B9: X200.8 | C9: Sb | D9: Sb | F9: Sb
A10: Antimony (dissolved) | B10: X200.8D | C10: Sb-DIS
A11: Apparent Color (unfiltered) | B11: 2120B | C11: APCOLR
A12: Arsenic | B12: X200.8 | C12: As | D12: As | F12: As
A13: Arsenic (dissolved) | B13: X200.8D | C13: As-DIS
A14: Barium | B14: X200.8 | C14: Ba | D14: Ba | E14: Ba | F14: Ba
A15: Barium (dissolved) | B15: X200.8D | C15: Ba-DIS
A16: Beryllium | B16: X200.8 | C16: Be | D16: Be | F16: Be
A17: Beryllium (dissolved) | B17: X200.8D | C17: Be-DIS
A18: Bicarbonate (as CaCO3) | B18: 2320B | C18: mide | D18: HCO3Ca | E18: HCO3Ca
A19: Bicarbonate (as HCO3) | B19: 2320B | C19: HCO3 | E19: HCO3
A20: Boron | B20: X200.7 | C20: B | D20: B | E20: B | F20: B
A21: Boron (dissolved) | B21: X200.7D | C21: B-DIS
A22: Bromate | B22: 300.1B | C22: BrO3
A23: Bromide | B23: 300.1B | C23: Br | D23: Br
A24: Cadmium | B24: X200.8 | C24: Cd | D24: Cd | F24: Cd
A25: Cadmium (dissolved) | B25: X200.8D | C25: Cd-DIS
A26: Calcium | B26: X200.7 | C26: Ca | D26: Ca | E26: Ca | F26: Ca
A27: Calcium (dissolved) | B27: X200.7D | C27: Ca-DIS
A28: Calcium Hardness | B28: X200.7 | C28: CaHRD
A29: Carbonate (as CaCO3) | B29: 2320B | C29: CO3Ca | D29: CO3Ca | E29: CO3Ca
A30: Carbonate (as CO3) | B30: 2320B | C30: CO3 | E30: CO3
A31: Chlorate | B31: 300.1B | C31: CLO3
A32: Chloride | B32: X1-300.0 | C32: Cl | D32: Cl | E32: Cl
A33: Chlorite | B33: 300.1B | C33: CLO2
A34: Chromium | B34: X200.8 | C34: Cr | D34: Cr | F34: Cr
A35: Chromium (dissolved) | B35: X200.8D | C35: Cr-DIS
A36: Cobalt | B36: X200.8 | C36: Co | D36: Co | F36: Co
A37: Cobalt (dissolved) | B37: X200.8D | C37: Co-DIS
A38: Copper | B38: X200.8 | C38: Cu | D38: Cu | F38: Cu
A39: Copper (dissolved) | B39: X200.8D | C39: Cu-DIS
A40: Corrosivity | B40: CORROSIV | C40: CORROS
...
